Workbook

Sheet Raw Items
B1: Raw Items / Сирі предмети
B2: RU | C2: EN (Code) | D2: Тип | E2: Тир обробки | F2: Ціна
B3: Шар 1 (0-50)
B4: Земля | C4: DirtItem | D4: Filler | E4: 0 | F4: 1
B5: Корінь | C5: RootItem | D5: None | E5: Паливо | F5: 2
B6: Глина | C6: ClayItem | D6: Filler | E6: 1 | F6: 3
B7: Пісок | C7: SandItem | D7: MassMaterial | E7: 1 | F7: 5
B8: Кремінь | C8: FlintItem | D8: MassMaterial | E8: 0 | F8: 5
B9: Вапно | C9: LimeItem | D9: MassMaterial | E9: 1 | F9: 8
B10: Бурштин | C10: AmberShardItem | D10: RareMaterial | E10: 0 | F10: 30
B11: Шар 2 (50-250)
B12: Бруківка | C12: CobblestoneItem | D12: Filler | E12: 1 | F12: 5
B13: Мідна руда | C13: RawCopperItem | D13: MassMaterial | E13: 1 | F13: 20
B14: Вугілля | C14: CoalItem | D14: None | E14: Паливо | F14: 12
B15: Граніт | C15: GraniteItem | D15: Constructive | E15: 1 | F15: 10
B16: Андезит | C16: AndesiteItem | D16: Constructive | E16: 1 | F16: 10
B17: Олов'яна руда | C17: RawTinItem | D17: MassMaterial | E17: 2 | F17: 20
B18: Залізна руда | C18: RawIronItem | D18: MassMaterial | E18: 2 | F18: 35
B19: Шар 3 (250-500)
B20: Сланець | C20: SlateItem | D20: Filler | E20: 2 | F20: 15
B21: Мармур | C21: MarbleItem | D21: Constructive | E21: 2 | F21: 40
B22: Уламок габро | C22: GabbroShardItem | D22: Constructive | E22: 2 | F22: 30
B23: Золота руда | C23: RawGoldItem | D23: RareMaterial | E23: 3 | F23: 100
B24: Срібна руда | C24: RawSilverItem | D24: RareMaterial | E24: 3 | F24: 70
B25: Алмаз | C25: DiamondItem | D25: RareMaterial | E25: 3 | F25: 500
B26: Шар 4 (500-800)
B27: Базальт | C27: BasaltItem | D27: Filler | E27: 4 | F27: 30
B28: Кварцит | C28: QuartziteItem | D28: Constructive | E28: 4 | F28: 50
B29: Гнейс | C29: GneissItem | D29: Constructive | E29: 4 | F29: 60
B30: Кобальтова руда | C30: RawCobaltItem | D30: RareMaterial | E30: 4 | F30: 125
B31: Міфрилова руда | C31: RawMithrilItem | D31: RareMaterial | E31: 4 | F31: 500
B32: Антрацит | C32: AnthraciteItem | D32: None | E32: Паливо | F32: 200
B33: Шар 5 (800-1000)
B34: Перидотит | C34: PeridotiteItem | D34: Filler | E34: 5 | F34: 65
B35: Обсидіановий уламок | C35: ObsidianShardItem | D35: RareMaterial | E35: 5 | F35: 210
B36: Магматит | C36: MagmatiteItem | D36: Constructive | E36: 5 | F36: 160
B37: Уранова руда | C37: RawUraniumItem | D37: RareMaterial | E37: 5 | F37: 290
B38: Адамантитова руда | C38: RawAdamantiteItem | D38: RareMaterial | E38: 6 | F38: 650
B39: Титанова руда | C39: RawTitaniumItem | D39: RareMaterial | E39: 6 | F39: 2000

Sheet Ingots and Alloys
B1: Ingots and Alloys / Злитки та сплави
B2: RU | C2: EN (Code) | D2: Тип | E2: Тир обробки | F2: Ціна | G2: К-сть на виході
B3: Тир 2
B4: Мідний злиток | C4: CopperIngotItem | D4: MassMaterial | E4: 2 | F4: =ROUND(('Raw Items'!F13+0)/G4*1.2,0) -> 24 | G4: 1
B5: Олов'яний злиток | C5: TinIngotItem | D5: MassMaterial | E5: 2 | F5: =ROUND(('Raw Items'!F17+0)/G5*1.2,0) -> 24 | G5: 1
B6: Залізний злиток | C6: IronIngotItem | D6: MassMaterial | E6: 2 | F6: =ROUND(('Raw Items'!F18+0)/G6*1.2,0) -> 42 | G6: 1
B7: Бронзовий злиток | C7: BronzeIngotItem | D7: Constructive | E7: 2 | F7: =ROUND((F4+F5)/G7*1.2,0) -> 29 | G7: 2
B8: Сталевий злиток | C8: SteelIngotItem | D8: Constructive | E8: 2 | F8: =ROUND((F6+'Raw Items'!F14)/G8*1.2,0) -> 65 | G8: 1
B9: Тир 3
B10: Золотий злиток | C10: GoldIngotItem | D10: RareMaterial | E10: 3 | F10: =ROUND(('Raw Items'!F23+0)/G10*1.2,0) -> 120 | G10: 1
B11: Срібний злиток | C11: SilverIngotItem | D11: RareMaterial | E11: 3 | F11: =ROUND(('Raw Items'!F24+0)/G11*1.2,0) -> 84 | G11: 1
B12: Електрумовий злиток | C12: ElectrumIngotItem | D12: RareMaterial | E12: 3 | F12: =ROUND((F10+F11)/G12*1.2,0) -> 122 | G12: 2
B13: Тир 4
B14: Кобальтовий злиток | C14: CobaltIngotItem | D14: RareMaterial | E14: 4 | F14: =ROUND(('Raw Items'!F30+0)/G14*1.2,0) -> 150 | G14: 1
B15: Міфриловий злиток | C15: MithrilIngotItem | D15: RareMaterial | E15: 4 | F15: =ROUND(('Raw Items'!F31+0)/G15*1.2,0) -> 600 | G15: 1
B16: Лазуровий метал | C16: AzureMetalItem | D16: RareMaterial | E16: 4 | F16: =ROUND((F15+F14)/G16*1.2,0) -> 450 | G16: 2
B17: Темна сталь | C17: DarkSteelItem | D17: RareMaterial | E17: 4 | F17: =ROUND((F14+'Raw Items'!F32)/G17*1.2,0) -> 420 | G17: 1
B18: Тир 5
B19: Вогняна сталь | C19: FireSteelItem | D19: RareMaterial | E19: 5 | F19: =ROUND(('Raw Items'!F36+F17)/G19*1.2,0) -> 696 | G19: 1
B20: Обсидіанова сталь | C20: ObsidianSteelItem | D20: RareMaterial | E20: 5 | F20: =ROUND(('Raw Items'!F35+F17)/G20*1.2,0) -> 756 | G20: 1
B21: Урановий злиток | C21: UraniumIngotItem | D21: RareMaterial | E21: 5 | F21: =ROUND(('Raw Items'!F37+0)/G21*1.2,0) -> 348 | G21: 1
B22: Тир 6
B23: Адамантитовий злиток | C23: AdamantiteIngotItem | D23: RareMaterial | E23: 6 | F23: =ROUND(('Raw Items'!F38+0)/G23*1.2,0) -> 780 | G23: 1
B24: Титановий злиток | C24: TitaniumIngotItem | D24: RareMaterial | E24: 6 | F24: =ROUND(('Raw Items'!F39+0)/G24*1.2,0) -> 2400 | G24: 1
B25: Міфічний сплав | C25: MythicAlloyItem | D25: RareMaterial | E25: 6 | F25: =ROUND((F23+F24)/G25*1.2,0) -> 1908 | G25: 2
B26: Чорний титан | C26: BlackTitaniumItem | D26: RareMaterial | E26: 6 | F26: =ROUND((F24+'Raw Items'!F35)/G26*1.2,0) -> 3132 | G26: 1
B27: Зоряний метал | C27: StarMetalItem | D27: RareMaterial | E27: 6 | F27: =ROUND((F26+F21)/G27*1.2,0) -> 4176 | G27: 1

Sheet Building Materials
B1: Building Materials / Будматеріали
B2: RU | C2: EN (Code) | D2: Тип | E2: Тир обробки | F2: Ціна | G2: К-сть на виході
B3: Тир 1
B4: Будівельний розчин | C4: MortarItem | D4: Constructive | E4: 1 | F4: =ROUND(('Raw Items'!F9+'Raw Items'!F7)/G4*1.2,0) -> 16 | G4: 1
B5: Глиняна цегла | C5: ClayBrickItem | D5: Constructive | E5: 1 | F5: =ROUND(('Raw Items'!F6+'Raw Items'!F7)/G5*1.2,0) -> 10 | G5: 1
B6: Проста опора | C6: SimpleSupportItem | D6: Constructive | E6: 1 | F6: =ROUND(('Raw Items'!F5+'Raw Items'!F8)/G6*1.2,0) -> 8 | G6: 1
B7: Саманна цегла | C7: AdobeBrickItem | D7: Constructive | E7: 1 | F7: =ROUND(('Raw Items'!F4+'Raw Items'!F6)/G7*1.2,0) -> 5 | G7: 1
B8: Просте скло | C8: SimpleGlassItem | D8: Constructive | E8: 1 | F8: =ROUND(('Raw Items'!F7+0)/G8*1.2,0) -> 6 | G8: 1
B9: Глиняна черепиця | C9: ClayTileItem | D9: Constructive | E9: 1 | F9: =ROUND(('Raw Items'!F6+'Raw Items'!F8)/G9*1.2,0) -> 10 | G9: 1
B10: Тир 2
B11: Цементний розчин | C11: CementMortarItem | D11: Constructive | E11: 2 | F11: =ROUND((F4+'Raw Items'!F12)/G11*1.2,0) -> 25 | G11: 1
B12: Гранітна кладка | C12: GraniteMasonryItem | D12: Constructive | E12: 2 | F12: =ROUND(('Raw Items'!F15+'Raw Items'!F12)/G12*1.2,0) -> 18 | G12: 1
B13: Бронзова балка | C13: BronzeBeamItem | D13: Constructive | E13: 2 | F13: =ROUND(('Ingots and Alloys'!F7+'Ingots and Alloys'!F7)/G13*1.2,0) -> 70 | G13: 1
B14: Андезитова плита | C14: AndesiteSlabItem | D14: Constructive | E14: 2 | F14: =ROUND(('Raw Items'!F16+'Raw Items'!F16)/G14*1.2,0) -> 24 | G14: 1
B15: Мідне вікно | C15: CopperWindowItem | D15: Constructive | E15: 2 | F15: =ROUND(('Ingots and Alloys'!F4+F8)/G15*1.2,0) -> 36 | G15: 1
B16: Кам'яна черепиця | C16: StoneTileItem | D16: Constructive | E16: 2 | F16: =ROUND(('Raw Items'!F12+'Raw Items'!F9)/G16*1.2,0) -> 16 | G16: 1
B17: Тир 3
B18: Смоляна в'язка | C18: TarBinderItem | D18: Constructive | E18: 3 | F18: =ROUND((F4+'Raw Items'!F14)/G18*1.2,0) -> 34 | G18: 1
B19: Габрова цегла | C19: GabbroBrickItem | D19: Constructive | E19: 3 | F19: =ROUND(('Raw Items'!F22+'Raw Items'!F20)/G19*1.2,0) -> 54 | G19: 1
B20: Сталева балка | C20: SteelBeamItem | D20: Constructive | E20: 3 | F20: =ROUND(('Ingots and Alloys'!F8+'Ingots and Alloys'!F8)/G20*1.2,0) -> 156 | G20: 1
B21: Мармурова плита | C21: MarbleSlabItem | D21: Constructive | E21: 3 | F21: =ROUND(('Raw Items'!F21+'Raw Items'!F21)/G21*1.2,0) -> 96 | G21: 1
B22: Вітражне скло | C22: StainedGlassItem | D22: RareMaterial | E22: 3 | F22: =ROUND((F8+'Ingots and Alloys'!F10)/G22*1.2,0) -> 151 | G22: 1
B23: Сланцева черепиця | C23: SlateTileItem | D23: Constructive | E23: 3 | F23: =ROUND(('Raw Items'!F20+'Ingots and Alloys'!F8)/G23*1.2,0) -> 96 | G23: 1
B24: Тир 4
B25: Кварцовий клей | C25: QuartzGlueItem | D25: Constructive | E25: 4 | F25: =ROUND((F4+'Raw Items'!F28)/G25*1.2,0) -> 79 | G25: 1
B26: Базальтова цегла | C26: BasaltBrickItem | D26: Constructive | E26: 4 | F26: =ROUND(('Raw Items'!F27+'Raw Items'!F27)/G26*1.2,0) -> 72 | G26: 1
B27: Паля з темної сталі | C27: DarkSteelPileItem | D27: RareMaterial | E27: 4 | F27: =ROUND(('Ingots and Alloys'!F17+'Ingots and Alloys'!F17)/G27*1.2,0) -> 1008 | G27: 1
B28: Гнейсова плита | C28: GneissSlabItem | D28: Constructive | E28: 4 | F28: =ROUND(('Raw Items'!F29+'Raw Items'!F29)/G28*1.2,0) -> 144 | G28: 1
B29: Кварцове скло | C29: QuartzGlassItem | D29: Constructive | E29: 4 | F29: =ROUND((F22+'Raw Items'!F28)/G29*1.2,0) -> 241 | G29: 1
B30: Кобальтова черепиця | C30: CobaltTileItem | D30: RareMaterial | E30: 4 | F30: =ROUND(('Ingots and Alloys'!F14+F28)/G30*1.2,0) -> 353 | G30: 1
B31: Тир 5
B32: Магматична паста | C32: MagmaPasteItem | D32: Constructive | E32: 5 | F32: =ROUND((F4+'Raw Items'!F36)/G32*1.2,0) -> 211 | G32: 1
B33: Вогнетривка цегла | C33: FireproofBrickItem | D33: Constructive | E33: 5 | F33: =ROUND(('Raw Items'!F36+'Raw Items'!F34)/G33*1.2,0) -> 270 | G33: 1
B34: Паля з обсидіанової сталі | C34: ObsidianSteelPileItem | D34: RareMaterial | E34: 5 | F34: =ROUND(('Ingots and Alloys'!F20+'Ingots and Alloys'!F20)/G34*1.2,0) -> 1814 | G34: 1
B35: Перидотитова плита | C35: PeridotiteSlabItem | D35: Constructive | E35: 5 | F35: =ROUND(('Raw Items'!F34+F32)/G35*1.2,0) -> 331 | G35: 1
B36: Уранове скло | C36: UraniumGlassItem | D36: RareMaterial | E36: 5 | F36: =ROUND((F29+'Ingots and Alloys'!F21)/G36*1.2,0) -> 707 | G36: 1
B37: Вогнетривка черепиця | C37: FireproofTileItem | D37: RareMaterial | E37: 5 | F37: =ROUND(('Ingots and Alloys'!F19+F35)/G37*1.2,0) -> 1232 | G37: 1

Sheet Порівняння із заповнювачем
B1: Порівняння ресурсів із заповнювачем шару
B2: Ресурс | C2: Тип | D2: Ціна | E2: Блок | F2: Міцність блоку | G2: Середній дроп | H2: Дохід за 1 міцності | I2: Ціна до заповнювача | J2: Дохід до заповнювача
B3: Шар 1 (0-50)
B4: ='Raw Items'!B4 -> Земля | C4: ='Raw Items'!D4 -> Filler | D4: ='Raw Items'!F4 -> 1 | E4: Земля | F4: 10 | G4: 1 | H4: =D4*G4/F4 -> 0.1 | I4: =D4/D$4 -> 1 | J4: =H4/H$4 -> 1
B5: ='Raw Items'!B5 -> Корінь | C5: ='Raw Items'!D5 -> None | D5: ='Raw Items'!F5 -> 2 | E5: Коріння | F5: 12 | G5: 1 | H5: =D5*G5/F5 -> 0.16666667 | I5: =D5/D$4 -> 2 | J5: =H5/H$4 -> 1.6666667
B6: ='Raw Items'!B6 -> Глина | C6: ='Raw Items'!D6 -> Filler | D6: ='Raw Items'!F6 -> 3 | E6: Глина | F6: 12 | G6: 1 | H6: =D6*G6/F6 -> 0.25 | I6: =D6/D$4 -> 3 | J6: =H6/H$4 -> 2.5
B7: ='Raw Items'!B7 -> Пісок | C7: ='Raw Items'!D7 -> MassMaterial | D7: ='Raw Items'!F7 -> 5 | E7: Пісок | F7: 10 | G7: 1 | H7: =D7*G7/F7 -> 0.5 | I7: =D7/D$4 -> 5 | J7: =H7/H$4 -> 5
B8: ='Raw Items'!B8 -> Кремінь | C8: ='Raw Items'!D8 -> MassMaterial | D8: ='Raw Items'!F8 -> 5 | E8: Гравій | F8: 15 | G8: 1 | H8: =D8*G8/F8 -> 0.33333333 | I8: =D8/D$4 -> 5 | J8: =H8/H$4 -> 3.3333333
B9: ='Raw Items'!B9 -> Вапно | C9: ='Raw Items'!D9 -> MassMaterial | D9: ='Raw Items'!F9 -> 8 | E9: Вапняк | F9: 18 | G9: 1 | H9: =D9*G9/F9 -> 0.44444444 | I9: =D9/D$4 -> 8 | J9: =H9/H$4 -> 4.4444444
B10: ='Raw Items'!B10 -> Бурштин | C10: ='Raw Items'!D10 -> RareMaterial | D10: ='Raw Items'!F10 -> 30 | E10: Бурштин | F10: 25 | G10: 1 | H10: =D10*G10/F10 -> 1.2 | I10: =D10/D$4 -> 30 | J10: =H10/H$4 -> 12
B11: Шар 2 (50-250)
B12: ='Raw Items'!B12 -> Бруківка | C12: ='Raw Items'!D12 -> Filler | D12: ='Raw Items'!F12 -> 5 | E12: Камінь | F12: 25 | G12: 1 | H12: =D12*G12/F12 -> 0.2 | I12: =D12/D$12 -> 1 | J12: =H12/H$12 -> 1
B13: ='Raw Items'!B13 -> Мідна руда | C13: ='Raw Items'!D13 -> MassMaterial | D13: ='Raw Items'!F13 -> 20 | E13: Мідь | F13: 30 | G13: 1 | H13: =D13*G13/F13 -> 0.66666667 | I13: =D13/D$12 -> 4 | J13: =H13/H$12 -> 3.3333333
B14: ='Raw Items'!B14 -> Вугілля | C14: ='Raw Items'!D14 -> None | D14: ='Raw Items'!F14 -> 12 | E14: Вугілля | F14: 30 | G14: 3.5 | H14: =D14*G14/F14 -> 1.4 | I14: =D14/D$12 -> 2.4 | J14: =H14/H$12 -> 7
B15: ='Raw Items'!B15 -> Граніт | C15: ='Raw Items'!D15 -> Constructive | D15: ='Raw Items'!F15 -> 10 | E15: Граніт | F15: 45 | G15: 1 | H15: =D15*G15/F15 -> 0.22222222 | I15: =D15/D$12 -> 2 | J15: =H15/H$12 -> 1.1111111
B16: ='Raw Items'!B16 -> Андезит | C16: ='Raw Items'!D16 -> Constructive | D16: ='Raw Items'!F16 -> 10 | E16: Андезит | F16: 40 | G16: 1 | H16: =D16*G16/F16 -> 0.25 | I16: =D16/D$12 -> 2 | J16: =H16/H$12 -> 1.25
B17: ='Raw Items'!B17 -> Олов'яна руда | C17: ='Raw Items'!D17 -> MassMaterial | D17: ='Raw Items'!F17 -> 20 | E17: Олово | F17: 35 | G17: 1 | H17: =D17*G17/F17 -> 0.57142857 | I17: =D17/D$12 -> 4 | J17: =H17/H$12 -> 2.8571429
B18: ='Raw Items'!B18 -> Залізна руда | C18: ='Raw Items'!D18 -> MassMaterial | D18: ='Raw Items'!F18 -> 35 | E18: Залізо | F18: 60 | G18: 1 | H18: =D18*G18/F18 -> 0.58333333 | I18: =D18/D$12 -> 7 | J18: =H18/H$12 -> 2.9166667
B19: Шар 3 (250-500)
B20: ='Raw Items'!B20 -> Сланець | C20: ='Raw Items'!D20 -> Filler | D20: ='Raw Items'!F20 -> 15 | E20: Сланець | F20: 60 | G20: 1 | H20: =D20*G20/F20 -> 0.25 | I20: =D20/D$20 -> 1 | J20: =H20/H$20 -> 1
B21: ='Raw Items'!B21 -> Мармур | C21: ='Raw Items'!D21 -> Constructive | D21: ='Raw Items'!F21 -> 40 | E21: Мармур | F21: 75 | G21: 1 | H21: =D21*G21/F21 -> 0.53333333 | I21: =D21/D$20 -> 2.6666667 | J21: =H21/H$20 -> 2.1333333
B22: ='Raw Items'!B22 -> Уламок габро | C22: ='Raw Items'!D22 -> Constructive | D22: ='Raw Items'!F22 -> 30 | E22: Габро | F22: 85 | G22: 1 | H22: =D22*G22/F22 -> 0.35294118 | I22: =D22/D$20 -> 2 | J22: =H22/H$20 -> 1.4117647
B23: ='Raw Items'!B23 -> Золота руда | C23: ='Raw Items'!D23 -> RareMaterial | D23: ='Raw Items'!F23 -> 100 | E23: Золото | F23: 45 | G23: 1 | H23: =D23*G23/F23 -> 2.2222222 | I23: =D23/D$20 -> 6.6666667 | J23: =H23/H$20 -> 8.8888889
B24: ='Raw Items'!B24 -> Срібна руда | C24: ='Raw Items'!D24 -> RareMaterial | D24: ='Raw Items'!F24 -> 70 | E24: Срібло | F24: 70 | G24: 1 | H24: =D24*G24/F24 -> 1 | I24: =D24/D$20 -> 4.6666667 | J24: =H24/H$20 -> 4
B25: ='Raw Items'!B25 -> Алмаз | C25: ='Raw Items'!D25 -> RareMaterial | D25: ='Raw Items'!F25 -> 500 | E25: Алмаз | F25: 200 | G25: 1 | H25: =D25*G25/F25 -> 2.5 | I25: =D25/D$20 -> 33.333333 | J25: =H25/H$20 -> 10
B26: Шар 4 (500-800)
B27: ='Raw Items'!B27 -> Базальт | C27: ='Raw Items'!D27 -> Filler | D27: ='Raw Items'!F27 -> 30 | E27: Базальт | F27: 130 | G27: 1 | H27: =D27*G27/F27 -> 0.23076923 | I27: =D27/D$27 -> 1 | J27: =H27/H$27 -> 1
B28: ='Raw Items'!B28 -> Кварцит | C28: ='Raw Items'!D28 -> Constructive | D28: ='Raw Items'!F28 -> 50 | E28: Кварцит | F28: 150 | G28: 1 | H28: =D28*G28/F28 -> 0.33333333 | I28: =D28/D$27 -> 1.6666667 | J28: =H28/H$27 -> 1.4444444
B29: ='Raw Items'!B29 -> Гнейс | C29: ='Raw Items'!D29 -> Constructive | D29: ='Raw Items'!F29 -> 60 | E29: Гнейс | F29: 160 | G29: 1 | H29: =D29*G29/F29 -> 0.375 | I29: =D29/D$27 -> 2 | J29: =H29/H$27 -> 1.625
B30: ='Raw Items'!B30 -> Кобальтова руда | C30: ='Raw Items'!D30 -> RareMaterial | D30: ='Raw Items'!F30 -> 125 | E30: Кобальт | F30: 180 | G30: 1 | H30: =D30*G30/F30 -> 0.69444444 | I30: =D30/D$27 -> 4.1666667 | J30: =H30/H$27 -> 3.0092593
B31: ='Raw Items'!B31 -> Міфрилова руда | C31: ='Raw Items'!D31 -> RareMaterial | D31: ='Raw Items'!F31 -> 500 | E31: Міфрил | F31: 220 | G31: 1 | H31: =D31*G31/F31 -> 2.2727273 | I31: =D31/D$27 -> 16.666667 | J31: =H31/H$27 -> 9.8484848
B32: ='Raw Items'!B32 -> Антрацит | C32: ='Raw Items'!D32 -> None | D32: ='Raw Items'!F32 -> 200 | E32: Антрацит | F32: 170 | G32: 2.5 | H32: =D32*G32/F32 -> 2.9411765 | I32: =D32/D$27 -> 6.6666667 | J32: =H32/H$27 -> 12.745098
B33: Шар 5 (800-1000)
B34: ='Raw Items'!B34 -> Перидотит | C34: ='Raw Items'!D34 -> Filler | D34: ='Raw Items'!F34 -> 65 | E34: Перидотит | F34: 250 | G34: 1 | H34: =D34*G34/F34 -> 0.26 | I34: =D34/D$34 -> 1 | J34: =H34/H$34 -> 1
B35: ='Raw Items'!B35 -> Обсидіановий уламок | C35: ='Raw Items'!D35 -> RareMaterial | D35: ='Raw Items'!F35 -> 210 | E35: Обсидіан | F35: 280 | G35: 1 | H35: =D35*G35/F35 -> 0.75 | I35: =D35/D$34 -> 3.2307692 | J35: =H35/H$34 -> 2.8846154
B36: ='Raw Items'!B36 -> Магматит | C36: ='Raw Items'!D36 -> Constructive | D36: ='Raw Items'!F36 -> 160 | E36: Магматит | F36: 320 | G36: 1 | H36: =D36*G36/F36 -> 0.5 | I36: =D36/D$34 -> 2.4615385 | J36: =H36/H$34 -> 1.9230769
B37: ='Raw Items'!B37 -> Уранова руда | C37: ='Raw Items'!D37 -> RareMaterial | D37: ='Raw Items'!F37 -> 290 | E37: Уран | F37: 360 | G37: 1 | H37: =D37*G37/F37 -> 0.80555556 | I37: =D37/D$34 -> 4.4615385 | J37: =H37/H$34 -> 3.0982906
B38: ='Raw Items'!B38 -> Адамантитова руда | C38: ='Raw Items'!D38 -> RareMaterial | D38: ='Raw Items'!F38 -> 650 | E38: Адамантит | F38: 400 | G38: 1 | H38: =D38*G38/F38 -> 1.625 | I38: =D38/D$34 -> 10 | J38: =H38/H$34 -> 6.25
B39: ='Raw Items'!B39 -> Титанова руда | C39: ='Raw Items'!D39 -> RareMaterial | D39: ='Raw Items'!F39 -> 2000 | E39: Титан | F39: 450 | G39: 1 | H39: =D39*G39/F39 -> 4.4444444 | I39: =D39/D$34 -> 30.769231 | J39: =H39/H$34 -> 17.094017
B41: Як читати
...
